[32mINFO    [0m juju.model:model.py:2087 Deploying local:jammy/postgresql-k8s-3
[32mINFO    [0m juju.model:model.py:2947 Waiting for model:
  test-storage-postgresql-k8s/0 [allocating] waiting: agent initialising
[32mINFO    [0m juju.model:model.py:2947 Waiting for model:
  test-storage-postgresql-k8s/0 [executing] waiting: awaiting for cluster to start
[32mINFO    [0m juju.model:model.py:2947 Waiting for model:
  test-storage-postgresql-k8s/0 [executing] waiting: awaiting for primary endpoint to be ready
[32mINFO    [0m juju.model:model.py:2947 Waiting for model:
  test-storage-postgresql-k8s/0 [executing] waiting: awaiting for primary endpoint to be ready
[32mINFO    [0m juju.model:model.py:2947 Waiting for model:
  test-storage-postgresql-k8s/0 [idle] active:
[32mINFO    [0m pytest_operator.plugin:plugin.py:784 Model status:

Model  Controller          Cloud/Region        Version  SLA          Timestamp
test   microk8s-localhost  microk8s/localhost  3.1.7    unsupported  02:17:04Z

App                          Version  Status   Scale  Charm           Channel  Rev  Address         Exposed  Message
postgresql-k8s                        waiting    0/3  postgresql-k8s             2  10.152.183.96   no       installing agent
test-storage-postgresql-k8s  14.10    active       1  postgresql-k8s             3  10.152.183.205  no       

Unit                            Workload  Agent       Address      Ports  Message
postgresql-k8s/0                waiting   allocating                      installing agent
postgresql-k8s/1                waiting   allocating                      installing agent
postgresql-k8s/2                waiting   allocating                      installing agent
test-storage-postgresql-k8s/0*  active    idle        10.1.47.163         

[32mINFO    [0m pytest_operator.plugin:plugin.py:790 Juju error logs:

unit-postgresql-k8s-2: 01:33:18 ERROR unit.postgresql-k8s/2.juju-log Cluster upgrade failed, ensure pre-upgrade checks are ran first.
unit-postgresql-k8s-0: 01:46:07 ERROR unit.postgresql-k8s/0.juju-log Cluster upgrade failed, ensure pre-upgrade checks are ran first.
unit-postgresql-k8s-0: 01:57:51 ERROR unit.postgresql-k8s/0.juju-log database-peers:3: Uncaught exception while in charm code:
Traceback (most recent call last):
  File "/var/lib/juju/agents/unit-postgresql-k8s-0/charm/venv/ops/model.py", line 2955, in _run
    result = subprocess.run(args, **kwargs)  # type: ignore
  File "/usr/lib/python3.10/subprocess.py", line 526, in run
    raise CalledProcessError(retcode, process.args,
subprocess.CalledProcessError: Command '('/var/lib/juju/tools/unit-postgresql-k8s-0/relation-get', '-r', '5', '-', 'postgresql-k8s', '--app', '--format=json')' returned non-zero exit status 1.

The above exception was the direct cause of the following exception:

Traceback (most recent call last):
  File "/var/lib/juju/agents/unit-postgresql-k8s-0/charm/./src/charm.py", line 1574, in <module>
    main(PostgresqlOperatorCharm, use_juju_for_storage=True)
  File "/var/lib/juju/agents/unit-postgresql-k8s-0/charm/venv/ops/main.py", line 436, in main
    _emit_charm_event(charm, dispatcher.event_name)
  File "/var/lib/juju/agents/unit-postgresql-k8s-0/charm/venv/ops/main.py", line 144, in _emit_charm_event
    event_to_emit.emit(*args, **kwargs)
  File "/var/lib/juju/agents/unit-postgresql-k8s-0/charm/venv/ops/framework.py", line 351, in emit
    framework._emit(event)
  File "/var/lib/juju/agents/unit-postgresql-k8s-0/charm/venv/ops/framework.py", line 853, in _emit
    self._reemit(event_path)
  File "/var/lib/juju/agents/unit-postgresql-k8s-0/charm/venv/ops/framework.py", line 942, in _reemit
    custom_handler(event)
  File "/var/lib/juju/agents/unit-postgresql-k8s-0/charm/./src/charm.py", line 384, in _on_peer_relation_changed
    self.update_config()
  File "/var/lib/juju/agents/unit-postgresql-k8s-0/charm/./src/charm.py", line 1379, in update_config
    is_no_sync_member=self.upgrade.is_no_sync_member,
  File "/var/lib/juju/agents/unit-postgresql-k8s-0/charm/src/upgrade.py", line 61, in is_no_sync_member
    sync_standbys = self.peer_relation.data[self.charm.app].get("sync-standbys")
  File "/usr/lib/python3.10/_collections_abc.py", line 824, in get
    return self[key]
  File "/var/lib/juju/agents/unit-postgresql-k8s-0/charm/venv/ops/model.py", line 1685, in __getitem__
    return super().__getitem__(key)
  File "/var/lib/juju/agents/unit-postgresql-k8s-0/charm/venv/ops/model.py", line 790, in __getitem__
    return self._data[key]
  File "/var/lib/juju/agents/unit-postgresql-k8s-0/charm/venv/ops/model.py", line 774, in _data
    data = self._lazy_data = self._load()
  File "/var/lib/juju/agents/unit-postgresql-k8s-0/charm/venv/ops/model.py", line 1569, in _load
    return self._backend.relation_get(self.relation.id, self._entity.name, self._is_app)
  File "/var/lib/juju/agents/unit-postgresql-k8s-0/charm/venv/ops/model.py", line 3036, in relation_get
    raw_data_content = self._run(*args, return_output=True, use_json=True)
  File "/var/lib/juju/agents/unit-postgresql-k8s-0/charm/venv/ops/model.py", line 2957, in _run
    raise ModelError(e.stderr) from e
ops.model.ModelError: ERROR permission denied

unit-postgresql-k8s-2: 01:57:51 ERROR juju.worker.uniter.context cannot apply changes: permission denied
unit-postgresql-k8s-2: 01:57:51 ERROR juju.worker.uniter.operation hook "update-status" (via hook dispatching script: dispatch) failed: permission denied

[32mINFO    [0m pytest_operator.plugin:plugin.py:856 Forgetting main...