{"uid":"d4fa85c85573ba0c","name":"test_fail_and_rollback","fullName":"tests.integration.ha_tests.test_upgrade#test_fail_and_rollback","historyId":"4b61a31bc9ec6b0bfc0d181346179a2b","time":{"start":1707701997699,"stop":1707702740370,"duration":742671},"status":"broken","statusMessage":"asyncio.exceptions.TimeoutError","statusTrace":"Traceback (most recent call last):\n  File \"/home/runner/work/postgresql-k8s-operator/postgresql-k8s-operator/.tox/integration/lib/python3.10/site-packages/juju/utils.py\", line 129, in _block\n    await jasyncio.sleep(wait_period)\n  File \"/usr/lib/python3.10/asyncio/tasks.py\", line 605, in sleep\n    return await future\nasyncio.exceptions.CancelledError\n\nDuring handling of the above exception, another exception occurred:\n\nTraceback (most recent call last):\n  File \"/usr/lib/python3.10/asyncio/tasks.py\", line 456, in wait_for\n    return fut.result()\nasyncio.exceptions.CancelledError\n\nThe above exception was the direct cause of the following exception:\n\nTraceback (most recent call last):\n  File \"/home/runner/work/postgresql-k8s-operator/postgresql-k8s-operator/.tox/integration/lib/python3.10/site-packages/_pytest/runner.py\", line 345, in from_call\n    result: Optional[TResult] = func()\n  File \"/home/runner/work/postgresql-k8s-operator/postgresql-k8s-operator/.tox/integration/lib/python3.10/site-packages/_pytest/runner.py\", line 266, in <lambda>\n    lambda: ihook(item=item, **kwds), when=when, reraise=reraise\n  File \"/home/runner/work/postgresql-k8s-operator/postgresql-k8s-operator/.tox/integration/lib/python3.10/site-packages/pluggy/_hooks.py\", line 493, in __call__\n    return self._hookexec(self.name, self._hookimpls, kwargs, firstresult)\n  File \"/home/runner/work/postgresql-k8s-operator/postgresql-k8s-operator/.tox/integration/lib/python3.10/site-packages/pluggy/_manager.py\", line 115, in _hookexec\n    return self._inner_hookexec(hook_name, methods, kwargs, firstresult)\n  File \"/home/runner/work/postgresql-k8s-operator/postgresql-k8s-operator/.tox/integration/lib/python3.10/site-packages/pluggy/_callers.py\", line 152, in _multicall\n    return outcome.get_result()\n  File \"/home/runner/work/postgresql-k8s-operator/postgresql-k8s-operator/.tox/integration/lib/python3.10/site-packages/pluggy/_result.py\", line 114, in get_result\n    raise exc.with_traceback(exc.__traceback__)\n  File \"/home/runner/work/postgresql-k8s-operator/postgresql-k8s-operator/.tox/integration/lib/python3.10/site-packages/pluggy/_callers.py\", line 137, in _multicall\n    teardown.throw(outcome._exception)\n  File \"/home/runner/work/postgresql-k8s-operator/postgresql-k8s-operator/.tox/integration/lib/python3.10/site-packages/_pytest/threadexception.py\", line 87, in pytest_runtest_call\n    yield from thread_exception_runtest_hook()\n  File \"/home/runner/work/postgresql-k8s-operator/postgresql-k8s-operator/.tox/integration/lib/python3.10/site-packages/_pytest/threadexception.py\", line 63, in thread_exception_runtest_hook\n    yield\n  File \"/home/runner/work/postgresql-k8s-operator/postgresql-k8s-operator/.tox/integration/lib/python3.10/site-packages/pluggy/_callers.py\", line 137, in _multicall\n    teardown.throw(outcome._exception)\n  File \"/home/runner/work/postgresql-k8s-operator/postgresql-k8s-operator/.tox/integration/lib/python3.10/site-packages/_pytest/unraisableexception.py\", line 90, in pytest_runtest_call\n    yield from unraisable_exception_runtest_hook()\n  File \"/home/runner/work/postgresql-k8s-operator/postgresql-k8s-operator/.tox/integration/lib/python3.10/site-packages/_pytest/unraisableexception.py\", line 65, in unraisable_exception_runtest_hook\n    yield\n  File \"/home/runner/work/postgresql-k8s-operator/postgresql-k8s-operator/.tox/integration/lib/python3.10/site-packages/pluggy/_callers.py\", line 137, in _multicall\n    teardown.throw(outcome._exception)\n  File \"/home/runner/work/postgresql-k8s-operator/postgresql-k8s-operator/.tox/integration/lib/python3.10/site-packages/_pytest/logging.py\", line 839, in pytest_runtest_call\n    yield from self._runtest_for(item, \"call\")\n  File \"/home/runner/work/postgresql-k8s-operator/postgresql-k8s-operator/.tox/integration/lib/python3.10/site-packages/_pytest/logging.py\", line 822, in _runtest_for\n    yield\n  File \"/home/runner/work/postgresql-k8s-operator/postgresql-k8s-operator/.tox/integration/lib/python3.10/site-packages/pluggy/_callers.py\", line 137, in _multicall\n    teardown.throw(outcome._exception)\n  File \"/home/runner/work/postgresql-k8s-operator/postgresql-k8s-operator/.tox/integration/lib/python3.10/site-packages/_pytest/capture.py\", line 882, in pytest_runtest_call\n    return (yield)\n  File \"/home/runner/work/postgresql-k8s-operator/postgresql-k8s-operator/.tox/integration/lib/python3.10/site-packages/pluggy/_callers.py\", line 137, in _multicall\n    teardown.throw(outcome._exception)\n  File \"/home/runner/work/postgresql-k8s-operator/postgresql-k8s-operator/.tox/integration/lib/python3.10/site-packages/_pytest/skipping.py\", line 257, in pytest_runtest_call\n    return (yield)\n  File \"/home/runner/work/postgresql-k8s-operator/postgresql-k8s-operator/.tox/integration/lib/python3.10/site-packages/pluggy/_callers.py\", line 77, in _multicall\n    res = hook_impl.function(*args)\n  File \"/home/runner/work/postgresql-k8s-operator/postgresql-k8s-operator/.tox/integration/lib/python3.10/site-packages/_pytest/runner.py\", line 181, in pytest_runtest_call\n    raise e\n  File \"/home/runner/work/postgresql-k8s-operator/postgresql-k8s-operator/.tox/integration/lib/python3.10/site-packages/_pytest/runner.py\", line 173, in pytest_runtest_call\n    item.runtest()\n  File \"/home/runner/work/postgresql-k8s-operator/postgresql-k8s-operator/.tox/integration/lib/python3.10/site-packages/_pytest/python.py\", line 1836, in runtest\n    self.ihook.pytest_pyfunc_call(pyfuncitem=self)\n  File \"/home/runner/work/postgresql-k8s-operator/postgresql-k8s-operator/.tox/integration/lib/python3.10/site-packages/pluggy/_hooks.py\", line 493, in __call__\n    return self._hookexec(self.name, self._hookimpls, kwargs, firstresult)\n  File \"/home/runner/work/postgresql-k8s-operator/postgresql-k8s-operator/.tox/integration/lib/python3.10/site-packages/pluggy/_manager.py\", line 115, in _hookexec\n    return self._inner_hookexec(hook_name, methods, kwargs, firstresult)\n  File \"/home/runner/work/postgresql-k8s-operator/postgresql-k8s-operator/.tox/integration/lib/python3.10/site-packages/pluggy/_callers.py\", line 152, in _multicall\n    return outcome.get_result()\n  File \"/home/runner/work/postgresql-k8s-operator/postgresql-k8s-operator/.tox/integration/lib/python3.10/site-packages/pluggy/_result.py\", line 114, in get_result\n    raise exc.with_traceback(exc.__traceback__)\n  File \"/home/runner/work/postgresql-k8s-operator/postgresql-k8s-operator/.tox/integration/lib/python3.10/site-packages/pluggy/_callers.py\", line 77, in _multicall\n    res = hook_impl.function(*args)\n  File \"/home/runner/work/postgresql-k8s-operator/postgresql-k8s-operator/.tox/integration/lib/python3.10/site-packages/_pytest/python.py\", line 193, in pytest_pyfunc_call\n    result = testfunction(**testargs)\n  File \"/home/runner/work/postgresql-k8s-operator/postgresql-k8s-operator/.tox/integration/lib/python3.10/site-packages/pytest_asyncio/plugin.py\", line 532, in inner\n    _loop.run_until_complete(task)\n  File \"/usr/lib/python3.10/asyncio/base_events.py\", line 649, in run_until_complete\n    return future.result()\n  File \"/home/runner/work/postgresql-k8s-operator/postgresql-k8s-operator/tests/integration/ha_tests/test_upgrade.py\", line 217, in test_fail_and_rollback\n    await ops_test.model.block_until(\n  File \"/home/runner/work/postgresql-k8s-operator/postgresql-k8s-operator/.tox/integration/lib/python3.10/site-packages/juju/model.py\", line 1035, in block_until\n    await utils.block_until(done,\n  File \"/home/runner/work/postgresql-k8s-operator/postgresql-k8s-operator/.tox/integration/lib/python3.10/site-packages/juju/utils.py\", line 130, in block_until\n    await jasyncio.shield(jasyncio.wait_for(_block(), timeout))\n  File \"/usr/lib/python3.10/asyncio/tasks.py\", line 458, in wait_for\n    raise exceptions.TimeoutError() from exc\nasyncio.exceptions.TimeoutError","flaky":false,"newFailed":false,"newBroken":false,"newPassed":false,"retriesCount":0,"retriesStatusChange":false,"beforeStages":[{"name":"event_loop","time":{"start":1707701271393,"stop":1707701271393,"duration":0},"status":"passed","steps":[],"attachments":[],"parameters":[],"stepsCount":0,"shouldDisplayMessage":false,"attachmentsCount":0,"hasContent":false,"attachmentStep":false},{"name":"tmp_path_factory","time":{"start":1707701271393,"stop":1707701271393,"duration":0},"status":"passed","steps":[],"attachments":[],"parameters":[],"stepsCount":0,"shouldDisplayMessage":false,"attachmentsCount":0,"hasContent":false,"attachmentStep":false},{"name":"ops_test","time":{"start":1707701271393,"stop":1707701271626,"duration":233},"status":"passed","steps":[],"attachments":[],"parameters":[],"stepsCount":0,"shouldDisplayMessage":false,"attachmentsCount":0,"hasContent":false,"attachmentStep":false},{"name":"continuous_writes","time":{"start":1707701997699,"stop":1707701997699,"duration":0},"status":"passed","steps":[],"attachments":[],"parameters":[],"stepsCount":0,"shouldDisplayMessage":false,"attachmentsCount":0,"hasContent":false,"attachmentStep":false},{"name":"abort_on_fail","time":{"start":1707701997699,"stop":1707701997699,"duration":0},"status":"passed","steps":[],"attachments":[],"parameters":[],"stepsCount":0,"shouldDisplayMessage":false,"attachmentsCount":0,"hasContent":false,"attachmentStep":false}],"testStage":{"status":"broken","statusMessage":"asyncio.exceptions.TimeoutError","statusTrace":"Traceback (most recent call last):\n  File \"/home/runner/work/postgresql-k8s-operator/postgresql-k8s-operator/.tox/integration/lib/python3.10/site-packages/juju/utils.py\", line 129, in _block\n    await jasyncio.sleep(wait_period)\n  File \"/usr/lib/python3.10/asyncio/tasks.py\", line 605, in sleep\n    return await future\nasyncio.exceptions.CancelledError\n\nDuring handling of the above exception, another exception occurred:\n\nTraceback (most recent call last):\n  File \"/usr/lib/python3.10/asyncio/tasks.py\", line 456, in wait_for\n    return fut.result()\nasyncio.exceptions.CancelledError\n\nThe above exception was the direct cause of the following exception:\n\nTraceback (most recent call last):\n  File \"/home/runner/work/postgresql-k8s-operator/postgresql-k8s-operator/.tox/integration/lib/python3.10/site-packages/_pytest/runner.py\", line 345, in from_call\n    result: Optional[TResult] = func()\n  File \"/home/runner/work/postgresql-k8s-operator/postgresql-k8s-operator/.tox/integration/lib/python3.10/site-packages/_pytest/runner.py\", line 266, in <lambda>\n    lambda: ihook(item=item, **kwds), when=when, reraise=reraise\n  File \"/home/runner/work/postgresql-k8s-operator/postgresql-k8s-operator/.tox/integration/lib/python3.10/site-packages/pluggy/_hooks.py\", line 493, in __call__\n    return self._hookexec(self.name, self._hookimpls, kwargs, firstresult)\n  File \"/home/runner/work/postgresql-k8s-operator/postgresql-k8s-operator/.tox/integration/lib/python3.10/site-packages/pluggy/_manager.py\", line 115, in _hookexec\n    return self._inner_hookexec(hook_name, methods, kwargs, firstresult)\n  File \"/home/runner/work/postgresql-k8s-operator/postgresql-k8s-operator/.tox/integration/lib/python3.10/site-packages/pluggy/_callers.py\", line 152, in _multicall\n    return outcome.get_result()\n  File \"/home/runner/work/postgresql-k8s-operator/postgresql-k8s-operator/.tox/integration/lib/python3.10/site-packages/pluggy/_result.py\", line 114, in get_result\n    raise exc.with_traceback(exc.__traceback__)\n  File \"/home/runner/work/postgresql-k8s-operator/postgresql-k8s-operator/.tox/integration/lib/python3.10/site-packages/pluggy/_callers.py\", line 137, in _multicall\n    teardown.throw(outcome._exception)\n  File \"/home/runner/work/postgresql-k8s-operator/postgresql-k8s-operator/.tox/integration/lib/python3.10/site-packages/_pytest/threadexception.py\", line 87, in pytest_runtest_call\n    yield from thread_exception_runtest_hook()\n  File \"/home/runner/work/postgresql-k8s-operator/postgresql-k8s-operator/.tox/integration/lib/python3.10/site-packages/_pytest/threadexception.py\", line 63, in thread_exception_runtest_hook\n    yield\n  File \"/home/runner/work/postgresql-k8s-operator/postgresql-k8s-operator/.tox/integration/lib/python3.10/site-packages/pluggy/_callers.py\", line 137, in _multicall\n    teardown.throw(outcome._exception)\n  File \"/home/runner/work/postgresql-k8s-operator/postgresql-k8s-operator/.tox/integration/lib/python3.10/site-packages/_pytest/unraisableexception.py\", line 90, in pytest_runtest_call\n    yield from unraisable_exception_runtest_hook()\n  File \"/home/runner/work/postgresql-k8s-operator/postgresql-k8s-operator/.tox/integration/lib/python3.10/site-packages/_pytest/unraisableexception.py\", line 65, in unraisable_exception_runtest_hook\n    yield\n  File \"/home/runner/work/postgresql-k8s-operator/postgresql-k8s-operator/.tox/integration/lib/python3.10/site-packages/pluggy/_callers.py\", line 137, in _multicall\n    teardown.throw(outcome._exception)\n  File \"/home/runner/work/postgresql-k8s-operator/postgresql-k8s-operator/.tox/integration/lib/python3.10/site-packages/_pytest/logging.py\", line 839, in pytest_runtest_call\n    yield from self._runtest_for(item, \"call\")\n  File \"/home/runner/work/postgresql-k8s-operator/postgresql-k8s-operator/.tox/integration/lib/python3.10/site-packages/_pytest/logging.py\", line 822, in _runtest_for\n    yield\n  File \"/home/runner/work/postgresql-k8s-operator/postgresql-k8s-operator/.tox/integration/lib/python3.10/site-packages/pluggy/_callers.py\", line 137, in _multicall\n    teardown.throw(outcome._exception)\n  File \"/home/runner/work/postgresql-k8s-operator/postgresql-k8s-operator/.tox/integration/lib/python3.10/site-packages/_pytest/capture.py\", line 882, in pytest_runtest_call\n    return (yield)\n  File \"/home/runner/work/postgresql-k8s-operator/postgresql-k8s-operator/.tox/integration/lib/python3.10/site-packages/pluggy/_callers.py\", line 137, in _multicall\n    teardown.throw(outcome._exception)\n  File \"/home/runner/work/postgresql-k8s-operator/postgresql-k8s-operator/.tox/integration/lib/python3.10/site-packages/_pytest/skipping.py\", line 257, in pytest_runtest_call\n    return (yield)\n  File \"/home/runner/work/postgresql-k8s-operator/postgresql-k8s-operator/.tox/integration/lib/python3.10/site-packages/pluggy/_callers.py\", line 77, in _multicall\n    res = hook_impl.function(*args)\n  File \"/home/runner/work/postgresql-k8s-operator/postgresql-k8s-operator/.tox/integration/lib/python3.10/site-packages/_pytest/runner.py\", line 181, in pytest_runtest_call\n    raise e\n  File \"/home/runner/work/postgresql-k8s-operator/postgresql-k8s-operator/.tox/integration/lib/python3.10/site-packages/_pytest/runner.py\", line 173, in pytest_runtest_call\n    item.runtest()\n  File \"/home/runner/work/postgresql-k8s-operator/postgresql-k8s-operator/.tox/integration/lib/python3.10/site-packages/_pytest/python.py\", line 1836, in runtest\n    self.ihook.pytest_pyfunc_call(pyfuncitem=self)\n  File \"/home/runner/work/postgresql-k8s-operator/postgresql-k8s-operator/.tox/integration/lib/python3.10/site-packages/pluggy/_hooks.py\", line 493, in __call__\n    return self._hookexec(self.name, self._hookimpls, kwargs, firstresult)\n  File \"/home/runner/work/postgresql-k8s-operator/postgresql-k8s-operator/.tox/integration/lib/python3.10/site-packages/pluggy/_manager.py\", line 115, in _hookexec\n    return self._inner_hookexec(hook_name, methods, kwargs, firstresult)\n  File \"/home/runner/work/postgresql-k8s-operator/postgresql-k8s-operator/.tox/integration/lib/python3.10/site-packages/pluggy/_callers.py\", line 152, in _multicall\n    return outcome.get_result()\n  File \"/home/runner/work/postgresql-k8s-operator/postgresql-k8s-operator/.tox/integration/lib/python3.10/site-packages/pluggy/_result.py\", line 114, in get_result\n    raise exc.with_traceback(exc.__traceback__)\n  File \"/home/runner/work/postgresql-k8s-operator/postgresql-k8s-operator/.tox/integration/lib/python3.10/site-packages/pluggy/_callers.py\", line 77, in _multicall\n    res = hook_impl.function(*args)\n  File \"/home/runner/work/postgresql-k8s-operator/postgresql-k8s-operator/.tox/integration/lib/python3.10/site-packages/_pytest/python.py\", line 193, in pytest_pyfunc_call\n    result = testfunction(**testargs)\n  File \"/home/runner/work/postgresql-k8s-operator/postgresql-k8s-operator/.tox/integration/lib/python3.10/site-packages/pytest_asyncio/plugin.py\", line 532, in inner\n    _loop.run_until_complete(task)\n  File \"/usr/lib/python3.10/asyncio/base_events.py\", line 649, in run_until_complete\n    return future.result()\n  File \"/home/runner/work/postgresql-k8s-operator/postgresql-k8s-operator/tests/integration/ha_tests/test_upgrade.py\", line 217, in test_fail_and_rollback\n    await ops_test.model.block_until(\n  File \"/home/runner/work/postgresql-k8s-operator/postgresql-k8s-operator/.tox/integration/lib/python3.10/site-packages/juju/model.py\", line 1035, in block_until\n    await utils.block_until(done,\n  File \"/home/runner/work/postgresql-k8s-operator/postgresql-k8s-operator/.tox/integration/lib/python3.10/site-packages/juju/utils.py\", line 130, in block_until\n    await jasyncio.shield(jasyncio.wait_for(_block(), timeout))\n  File \"/usr/lib/python3.10/asyncio/tasks.py\", line 458, in wait_for\n    raise exceptions.TimeoutError() from exc\nasyncio.exceptions.TimeoutError","steps":[],"attachments":[{"uid":"86d0f98e03e45c28","name":"log","source":"86d0f98e03e45c28.txt","type":"text/plain","size":551628}],"parameters":[],"stepsCount":0,"shouldDisplayMessage":true,"attachmentsCount":1,"hasContent":true,"attachmentStep":false},"afterStages":[{"name":"continuous_writes::finalizer","time":{"start":1707702740405,"stop":1707702746446,"duration":6041},"status":"passed","steps":[],"attachments":[],"parameters":[],"stepsCount":0,"shouldDisplayMessage":false,"attachmentsCount":0,"hasContent":false,"attachmentStep":false},{"name":"ops_test::finalizer","time":{"start":1707702746446,"stop":1707702746902,"duration":456},"status":"passed","steps":[],"attachments":[],"parameters":[],"stepsCount":0,"shouldDisplayMessage":false,"attachmentsCount":0,"hasContent":false,"attachmentStep":false},{"name":"abort_on_fail::0","time":{"start":1707702746446,"stop":1707702746446,"duration":0},"status":"passed","steps":[],"attachments":[],"parameters":[],"stepsCount":0,"shouldDisplayMessage":false,"attachmentsCount":0,"hasContent":false,"attachmentStep":false},{"name":"event_loop::2","time":{"start":1707702746902,"stop":1707702746903,"duration":1},"status":"passed","steps":[],"attachments":[],"parameters":[],"stepsCount":0,"shouldDisplayMessage":false,"attachmentsCount":0,"hasContent":false,"attachmentStep":false},{"name":"event_loop::_close_event_loop","time":{"start":1707702746903,"stop":1707702746903,"duration":0},"status":"passed","steps":[],"attachments":[],"parameters":[],"stepsCount":0,"shouldDisplayMessage":false,"attachmentsCount":0,"hasContent":false,"attachmentStep":false},{"name":"event_loop::_provide_clean_event_loop","time":{"start":1707702746903,"stop":1707702746903,"duration":0},"status":"passed","steps":[],"attachments":[],"parameters":[],"stepsCount":0,"shouldDisplayMessage":false,"attachmentsCount":0,"hasContent":false,"attachmentStep":false}],"labels":[{"name":"tag","value":"abort_on_fail"},{"name":"tag","value":"group(1)"},{"name":"tag","value":"asyncio"},{"name":"parentSuite","value":"tests.integration.ha_tests"},{"name":"suite","value":"test_upgrade"},{"name":"host","value":"fv-az1016-149"},{"name":"thread","value":"12156-MainThread"},{"name":"framework","value":"pytest"},{"name":"language","value":"cpython3"},{"name":"package","value":"tests.integration.ha_tests.test_upgrade"},{"name":"resultFormat","value":"allure2"}],"parameters":[],"links":[],"hidden":false,"retry":false,"extra":{"severity":"normal","retries":[],"categories":[{"name":"Test defects","matchedStatuses":[],"flaky":false}],"history":{"statistic":{"failed":0,"broken":8,"skipped":2,"passed":2,"unknown":0,"total":12},"items":[{"uid":"bd8b1fb7669b3b8e","reportUrl":"../1880//#testresult/bd8b1fb7669b3b8e","status":"broken","statusDetails":"asyncio.exceptions.TimeoutError","time":{"start":1707615657549,"stop":1707616395496,"duration":737947}},{"uid":"ccc60d085f63c51c","reportUrl":"../1879//#testresult/ccc60d085f63c51c","status":"broken","statusDetails":"asyncio.exceptions.TimeoutError","time":{"start":1707529096168,"stop":1707529837704,"duration":741536}},{"uid":"8b2aed000f7408c3","reportUrl":"../1875//#testresult/8b2aed000f7408c3","status":"passed","time":{"start":1707442831388,"stop":1707443358259,"duration":526871}},{"uid":"f4f21ca68054c619","reportUrl":"../1870//#testresult/f4f21ca68054c619","status":"passed","time":{"start":1707356307443,"stop":1707356841320,"duration":533877}},{"uid":"f4cd8f1455fcd84b","reportUrl":"../1866//#testresult/f4cd8f1455fcd84b","status":"skipped","statusDetails":"XFAIL reason: aborted\n\n_pytest.outcomes.XFailed: aborted","time":{"start":1707269210534,"stop":1707269210534,"duration":0}},{"uid":"7ba106b4e7d85d57","reportUrl":"../1862//#testresult/7ba106b4e7d85d57","status":"skipped","statusDetails":"XFAIL reason: aborted\n\n_pytest.outcomes.XFailed: aborted","time":{"start":1707182890541,"stop":1707182890541,"duration":0}},{"uid":"f806faa7cb3c9235","reportUrl":"../1852//#testresult/f806faa7cb3c9235","status":"broken","statusDetails":"asyncio.exceptions.TimeoutError","time":{"start":1707097224752,"stop":1707097962244,"duration":737492}},{"uid":"565b7854f6e387a","reportUrl":"../1851//#testresult/565b7854f6e387a","status":"broken","statusDetails":"asyncio.exceptions.TimeoutError","time":{"start":1707010854276,"stop":1707011595333,"duration":741057}},{"uid":"f6b4787d768b2350","reportUrl":"../1850//#testresult/f6b4787d768b2350","status":"broken","statusDetails":"asyncio.exceptions.TimeoutError","time":{"start":1706924307434,"stop":1706925048433,"duration":740999}},{"uid":"de23d6cac0ae9f88","reportUrl":"../1842//#testresult/de23d6cac0ae9f88","status":"broken","statusDetails":"asyncio.exceptions.TimeoutError","time":{"start":1706838063132,"stop":1706838804887,"duration":741755}},{"uid":"93ee6adeebdcf7a5","reportUrl":"../1834//#testresult/93ee6adeebdcf7a5","status":"broken","statusDetails":"asyncio.exceptions.TimeoutError","time":{"start":1706751743275,"stop":1706752484607,"duration":741332}}]},"tags":["asyncio","abort_on_fail","group(1)"]},"source":"d4fa85c85573ba0c.json","parameterValues":[]}