[32mINFO    [0m juju.model:model.py:2097 Deploying local:jammy/postgresql-k8s-3
[32mINFO    [0m juju.model:model.py:2957 Waiting for model:
  test-storage-postgresql-k8s/0 [allocating] waiting: agent initialising
[32mINFO    [0m juju.model:model.py:2957 Waiting for model:
  test-storage-postgresql-k8s/0 [executing] waiting: awaiting for cluster to start
[32mINFO    [0m juju.model:model.py:2957 Waiting for model:
  test-storage-postgresql-k8s/0 [executing] waiting: awaiting for primary endpoint to be ready
[32mINFO    [0m juju.model:model.py:2957 Waiting for model:
  test-storage-postgresql-k8s/0 [executing] waiting: awaiting for primary endpoint to be ready
[32mINFO    [0m juju.model:model.py:2957 Waiting for model:
  test-storage-postgresql-k8s/0 [idle] active:
[32mINFO    [0m pytest_operator.plugin:plugin.py:834 Model status:

Model  Controller          Cloud/Region        Version  SLA          Timestamp
test   microk8s-localhost  microk8s/localhost  3.1.7    unsupported  02:09:26Z

App                          Version  Status  Scale  Charm           Channel  Rev  Address         Exposed  Message
postgresql-k8s               14.11    active      3  postgresql-k8s             2  10.152.183.159  no       
test-storage-postgresql-k8s  14.11    active      1  postgresql-k8s             3  10.152.183.240  no       

Unit                            Workload  Agent  Address       Ports  Message
postgresql-k8s/0                active    idle   10.1.189.159         
postgresql-k8s/1                active    idle   10.1.189.161         
postgresql-k8s/2*               active    idle   10.1.189.160         Primary
test-storage-postgresql-k8s/0*  active    idle   10.1.189.163         

[32mINFO    [0m pytest_operator.plugin:plugin.py:840 Juju error logs:

unit-postgresql-k8s-1: 01:36:31 ERROR unit.postgresql-k8s/1.juju-log Cluster upgrade failed, ensure pre-upgrade checks are ran first.
unit-postgresql-k8s-0: 01:49:50 ERROR unit.postgresql-k8s/0.juju-log Cluster upgrade failed, ensure pre-upgrade checks are ran first.
unit-postgresql-k8s-0: 02:02:33 ERROR unit.postgresql-k8s/0.juju-log Uncaught exception while in charm code:
Traceback (most recent call last):
  File "/var/lib/juju/agents/unit-postgresql-k8s-0/charm/venv/ops/model.py", line 3014, in _run
    result = subprocess.run(args, **kwargs)  # type: ignore
  File "/usr/lib/python3.10/subprocess.py", line 526, in run
    raise CalledProcessError(retcode, process.args,
subprocess.CalledProcessError: Command '('/var/lib/juju/tools/unit-postgresql-k8s-0/relation-get', '-r', '4', '-', 'postgresql-k8s', '--app', '--format=json')' returned non-zero exit status 1.

The above exception was the direct cause of the following exception:

Traceback (most recent call last):
  File "/var/lib/juju/agents/unit-postgresql-k8s-0/charm/./src/charm.py", line 1597, in <module>
    main(PostgresqlOperatorCharm, use_juju_for_storage=True)
  File "/var/lib/juju/agents/unit-postgresql-k8s-0/charm/venv/ops/main.py", line 456, in main
    _emit_charm_event(charm, dispatcher.event_name)
  File "/var/lib/juju/agents/unit-postgresql-k8s-0/charm/venv/ops/main.py", line 144, in _emit_charm_event
    event_to_emit.emit(*args, **kwargs)
  File "/var/lib/juju/agents/unit-postgresql-k8s-0/charm/venv/ops/framework.py", line 352, in emit
    framework._emit(event)
  File "/var/lib/juju/agents/unit-postgresql-k8s-0/charm/venv/ops/framework.py", line 865, in _emit
    self._reemit(event_path)
  File "/var/lib/juju/agents/unit-postgresql-k8s-0/charm/venv/ops/framework.py", line 955, in _reemit
    custom_handler(event)
  File "/var/lib/juju/agents/unit-postgresql-k8s-0/charm/./src/charm.py", line 1059, in _on_update_status
    if "restoring-backup" in self.app_peer_data:
  File "/var/lib/juju/agents/unit-postgresql-k8s-0/charm/venv/ops/model.py", line 787, in __contains__
    return key in self._data
  File "/var/lib/juju/agents/unit-postgresql-k8s-0/charm/venv/ops/model.py", line 780, in _data
    data = self._lazy_data = self._load()
  File "/var/lib/juju/agents/unit-postgresql-k8s-0/charm/venv/ops/model.py", line 1581, in _load
    return self._backend.relation_get(self.relation.id, self._entity.name, self._is_app)
  File "/var/lib/juju/agents/unit-postgresql-k8s-0/charm/venv/ops/model.py", line 3095, in relation_get
    raw_data_content = self._run(*args, return_output=True, use_json=True)
  File "/var/lib/juju/agents/unit-postgresql-k8s-0/charm/venv/ops/model.py", line 3016, in _run
    raise ModelError(e.stderr) from e
ops.model.ModelError: ERROR permission denied

controller-0: 02:02:39 ERROR juju.worker.caasapplicationprovisioner.runner exited "postgresql-k8s": cannot scale dying application to 0: application "postgresql-k8s" not found

[32mINFO    [0m pytest_operator.plugin:plugin.py:904 Forgetting main...