[32mINFO    [0m integration.test_backups:test_backups.py:77 deleting the previously created backups
[32mINFO    [0m pytest_operator.plugin:plugin.py:791 Model status:

Model  Controller          Cloud/Region        Version  SLA          Timestamp
test   microk8s-localhost  microk8s/localhost  3.1.7    unsupported  01:32:48Z

App                       Version  Status   Scale  Charm                     Channel        Rev  Address         Exposed  Message
postgresql-k8s-aws        14.11    waiting      2  postgresql-k8s                             0  10.152.183.237  no       installing agent
s3-integrator                      active       1  s3-integrator             latest/stable   13  10.152.183.142  no       
self-signed-certificates           active       1  self-signed-certificates  latest/stable   72  10.152.183.153  no       

Unit                         Workload  Agent  Address     Ports  Message
postgresql-k8s-aws/0         waiting   idle   10.1.2.205         Awaiting restart operation
postgresql-k8s-aws/1*        error     idle   10.1.2.204         hook failed: "certificates-relation-changed"
s3-integrator/0*             active    idle   10.1.2.200         
self-signed-certificates/0*  active    idle   10.1.2.201         

[32mINFO    [0m pytest_operator.plugin:plugin.py:797 Juju error logs:

unit-postgresql-k8s-aws-1: 01:32:46 ERROR unit.postgresql-k8s-aws/1.juju-log certificates:5: Uncaught exception while in charm code:
Traceback (most recent call last):
  File "/var/lib/juju/agents/unit-postgresql-k8s-aws-1/charm/venv/urllib3/connectionpool.py", line 791, in urlopen
    response = self._make_request(
  File "/var/lib/juju/agents/unit-postgresql-k8s-aws-1/charm/venv/urllib3/connectionpool.py", line 537, in _make_request
    response = conn.getresponse()
  File "/var/lib/juju/agents/unit-postgresql-k8s-aws-1/charm/venv/urllib3/connection.py", line 461, in getresponse
    httplib_response = super().getresponse()
  File "/usr/lib/python3.10/http/client.py", line 1375, in getresponse
    response.begin()
  File "/usr/lib/python3.10/http/client.py", line 318, in begin
    version, status, reason = self._read_status()
  File "/usr/lib/python3.10/http/client.py", line 279, in _read_status
    line = str(self.fp.readline(_MAXLINE + 1), "iso-8859-1")
  File "/usr/lib/python3.10/socket.py", line 705, in readinto
    return self._sock.recv_into(b)
ConnectionResetError: [Errno 104] Connection reset by peer

During handling of the above exception, another exception occurred:

Traceback (most recent call last):
  File "/var/lib/juju/agents/unit-postgresql-k8s-aws-1/charm/venv/requests/adapters.py", line 486, in send
    resp = conn.urlopen(
  File "/var/lib/juju/agents/unit-postgresql-k8s-aws-1/charm/venv/urllib3/connectionpool.py", line 845, in urlopen
    retries = retries.increment(
  File "/var/lib/juju/agents/unit-postgresql-k8s-aws-1/charm/venv/urllib3/util/retry.py", line 470, in increment
    raise reraise(type(error), error, _stacktrace)
  File "/var/lib/juju/agents/unit-postgresql-k8s-aws-1/charm/venv/urllib3/util/util.py", line 38, in reraise
    raise value.with_traceback(tb)
  File "/var/lib/juju/agents/unit-postgresql-k8s-aws-1/charm/venv/urllib3/connectionpool.py", line 791, in urlopen
    response = self._make_request(
  File "/var/lib/juju/agents/unit-postgresql-k8s-aws-1/charm/venv/urllib3/connectionpool.py", line 537, in _make_request
    response = conn.getresponse()
  File "/var/lib/juju/agents/unit-postgresql-k8s-aws-1/charm/venv/urllib3/connection.py", line 461, in getresponse
    httplib_response = super().getresponse()
  File "/usr/lib/python3.10/http/client.py", line 1375, in getresponse
    response.begin()
  File "/usr/lib/python3.10/http/client.py", line 318, in begin
    version, status, reason = self._read_status()
  File "/usr/lib/python3.10/http/client.py", line 279, in _read_status
    line = str(self.fp.readline(_MAXLINE + 1), "iso-8859-1")
  File "/usr/lib/python3.10/socket.py", line 705, in readinto
    return self._sock.recv_into(b)
urllib3.exceptions.ProtocolError: ('Connection aborted.', ConnectionResetError(104, 'Connection reset by peer'))

During handling of the above exception, another exception occurred:

Traceback (most recent call last):
  File "/var/lib/juju/agents/unit-postgresql-k8s-aws-1/charm/venv/tenacity/__init__.py", line 382, in __call__
    result = fn(*args, **kwargs)
  File "/var/lib/juju/agents/unit-postgresql-k8s-aws-1/charm/src/patroni.py", line 395, in reload_patroni_configuration
    requests.post(f"{self._patroni_url}/reload", verify=self._verify)
  File "/var/lib/juju/agents/unit-postgresql-k8s-aws-1/charm/venv/requests/api.py", line 115, in post
    return request("post", url, data=data, json=json, **kwargs)
  File "/var/lib/juju/agents/unit-postgresql-k8s-aws-1/charm/venv/requests/api.py", line 59, in request
    return session.request(method=method, url=url, **kwargs)
  File "/var/lib/juju/agents/unit-postgresql-k8s-aws-1/charm/venv/requests/sessions.py", line 589, in request
    resp = self.send(prep, **send_kwargs)
  File "/var/lib/juju/agents/unit-postgresql-k8s-aws-1/charm/venv/requests/sessions.py", line 703, in send
    r = adapter.send(request, **kwargs)
  File "/var/lib/juju/agents/unit-postgresql-k8s-aws-1/charm/venv/requests/adapters.py", line 501, in send
    raise ConnectionError(err, request=request)
requests.exceptions.ConnectionError: ('Connection aborted.', ConnectionResetError(104, 'Connection reset by peer'))

The above exception was the direct cause of the following exception:

Traceback (most recent call last):
  File "/var/lib/juju/agents/unit-postgresql-k8s-aws-1/charm/./src/charm.py", line 1585, in <module>
    main(PostgresqlOperatorCharm, use_juju_for_storage=True)
  File "/var/lib/juju/agents/unit-postgresql-k8s-aws-1/charm/venv/ops/main.py", line 456, in main
    _emit_charm_event(charm, dispatcher.event_name)
  File "/var/lib/juju/agents/unit-postgresql-k8s-aws-1/charm/venv/ops/main.py", line 144, in _emit_charm_event
    event_to_emit.emit(*args, **kwargs)
  File "/var/lib/juju/agents/unit-postgresql-k8s-aws-1/charm/venv/ops/framework.py", line 352, in emit
    framework._emit(event)
  File "/var/lib/juju/agents/unit-postgresql-k8s-aws-1/charm/venv/ops/framework.py", line 865, in _emit
    self._reemit(event_path)
  File "/var/lib/juju/agents/unit-postgresql-k8s-aws-1/charm/venv/ops/framework.py", line 955, in _reemit
    custom_handler(event)
  File "/var/lib/juju/agents/unit-postgresql-k8s-aws-1/charm/lib/charms/tls_certificates_interface/v2/tls_certificates.py", line 1822, in _on_relation_changed
    self.on.certificate_available.emit(
  File "/var/lib/juju/agents/unit-postgresql-k8s-aws-1/charm/venv/ops/framework.py", line 352, in emit
    framework._emit(event)
  File "/var/lib/juju/agents/unit-postgresql-k8s-aws-1/charm/venv/ops/framework.py", line 865, in _emit
    self._reemit(event_path)
  File "/var/lib/juju/agents/unit-postgresql-k8s-aws-1/charm/venv/ops/framework.py", line 955, in _reemit
    custom_handler(event)
  File "/var/lib/juju/agents/unit-postgresql-k8s-aws-1/charm/lib/charms/postgresql_k8s/v0/postgresql_tls.py", line 141, in _on_certificate_available
    if not self.charm.push_tls_files_to_workload():
  File "/var/lib/juju/agents/unit-postgresql-k8s-aws-1/charm/./src/charm.py", line 1316, in push_tls_files_to_workload
    return self.update_config()
  File "/var/lib/juju/agents/unit-postgresql-k8s-aws-1/charm/./src/charm.py", line 1408, in update_config
    self._handle_postgresql_restart_need()
  File "/var/lib/juju/agents/unit-postgresql-k8s-aws-1/charm/./src/charm.py", line 1461, in _handle_postgresql_restart_need
    self._patroni.reload_patroni_configuration()
  File "/var/lib/juju/agents/unit-postgresql-k8s-aws-1/charm/venv/tenacity/__init__.py", line 289, in wrapped_f
    return self(f, *args, **kw)
  File "/var/lib/juju/agents/unit-postgresql-k8s-aws-1/charm/venv/tenacity/__init__.py", line 379, in __call__
    do = self.iter(retry_state=retry_state)
  File "/var/lib/juju/agents/unit-postgresql-k8s-aws-1/charm/venv/tenacity/__init__.py", line 326, in iter
    raise retry_exc from fut.exception()
tenacity.RetryError: RetryError[<Future at 0x7f562791bf10 state=finished raised ConnectionError>]
unit-postgresql-k8s-aws-1: 01:32:46 ERROR juju.worker.uniter.operation hook "certificates-relation-changed" (via hook dispatching script: dispatch) failed: exit status 1

[32mINFO    [0m pytest_operator.plugin:plugin.py:861 Forgetting main...