{"uid":"dea77623301df108","name":"test_forceful_restart_without_data_and_transaction_logs","fullName":"tests.integration.ha_tests.test_self_healing#test_forceful_restart_without_data_and_transaction_logs","historyId":"1ab295315f12ae381caee21d2bb9082a","time":{"start":1706752243832,"stop":1706752361124,"duration":117292},"description":"A forceful restart with deleted data and without transaction logs (forced clone).","descriptionHtml":"<p>A forceful restart with deleted data and without transaction logs (forced clone).</p>\n","status":"failed","statusMessage":"AssertionError: secondary not up to date with the cluster after restarting.","statusTrace":"Traceback (most recent call last):\n  File \"/home/runner/work/postgresql-k8s-operator/postgresql-k8s-operator/.tox/integration/lib/python3.10/site-packages/_pytest/runner.py\", line 345, in from_call\n    result: Optional[TResult] = func()\n  File \"/home/runner/work/postgresql-k8s-operator/postgresql-k8s-operator/.tox/integration/lib/python3.10/site-packages/_pytest/runner.py\", line 266, in <lambda>\n    lambda: ihook(item=item, **kwds), when=when, reraise=reraise\n  File \"/home/runner/work/postgresql-k8s-operator/postgresql-k8s-operator/.tox/integration/lib/python3.10/site-packages/pluggy/_hooks.py\", line 493, in __call__\n    return self._hookexec(self.name, self._hookimpls, kwargs, firstresult)\n  File \"/home/runner/work/postgresql-k8s-operator/postgresql-k8s-operator/.tox/integration/lib/python3.10/site-packages/pluggy/_manager.py\", line 115, in _hookexec\n    return self._inner_hookexec(hook_name, methods, kwargs, firstresult)\n  File \"/home/runner/work/postgresql-k8s-operator/postgresql-k8s-operator/.tox/integration/lib/python3.10/site-packages/pluggy/_callers.py\", line 152, in _multicall\n    return outcome.get_result()\n  File \"/home/runner/work/postgresql-k8s-operator/postgresql-k8s-operator/.tox/integration/lib/python3.10/site-packages/pluggy/_result.py\", line 114, in get_result\n    raise exc.with_traceback(exc.__traceback__)\n  File \"/home/runner/work/postgresql-k8s-operator/postgresql-k8s-operator/.tox/integration/lib/python3.10/site-packages/pluggy/_callers.py\", line 137, in _multicall\n    teardown.throw(outcome._exception)\n  File \"/home/runner/work/postgresql-k8s-operator/postgresql-k8s-operator/.tox/integration/lib/python3.10/site-packages/_pytest/threadexception.py\", line 87, in pytest_runtest_call\n    yield from thread_exception_runtest_hook()\n  File \"/home/runner/work/postgresql-k8s-operator/postgresql-k8s-operator/.tox/integration/lib/python3.10/site-packages/_pytest/threadexception.py\", line 63, in thread_exception_runtest_hook\n    yield\n  File \"/home/runner/work/postgresql-k8s-operator/postgresql-k8s-operator/.tox/integration/lib/python3.10/site-packages/pluggy/_callers.py\", line 137, in _multicall\n    teardown.throw(outcome._exception)\n  File \"/home/runner/work/postgresql-k8s-operator/postgresql-k8s-operator/.tox/integration/lib/python3.10/site-packages/_pytest/unraisableexception.py\", line 90, in pytest_runtest_call\n    yield from unraisable_exception_runtest_hook()\n  File \"/home/runner/work/postgresql-k8s-operator/postgresql-k8s-operator/.tox/integration/lib/python3.10/site-packages/_pytest/unraisableexception.py\", line 65, in unraisable_exception_runtest_hook\n    yield\n  File \"/home/runner/work/postgresql-k8s-operator/postgresql-k8s-operator/.tox/integration/lib/python3.10/site-packages/pluggy/_callers.py\", line 137, in _multicall\n    teardown.throw(outcome._exception)\n  File \"/home/runner/work/postgresql-k8s-operator/postgresql-k8s-operator/.tox/integration/lib/python3.10/site-packages/_pytest/logging.py\", line 839, in pytest_runtest_call\n    yield from self._runtest_for(item, \"call\")\n  File \"/home/runner/work/postgresql-k8s-operator/postgresql-k8s-operator/.tox/integration/lib/python3.10/site-packages/_pytest/logging.py\", line 822, in _runtest_for\n    yield\n  File \"/home/runner/work/postgresql-k8s-operator/postgresql-k8s-operator/.tox/integration/lib/python3.10/site-packages/pluggy/_callers.py\", line 137, in _multicall\n    teardown.throw(outcome._exception)\n  File \"/home/runner/work/postgresql-k8s-operator/postgresql-k8s-operator/.tox/integration/lib/python3.10/site-packages/_pytest/capture.py\", line 882, in pytest_runtest_call\n    return (yield)\n  File \"/home/runner/work/postgresql-k8s-operator/postgresql-k8s-operator/.tox/integration/lib/python3.10/site-packages/pluggy/_callers.py\", line 137, in _multicall\n    teardown.throw(outcome._exception)\n  File \"/home/runner/work/postgresql-k8s-operator/postgresql-k8s-operator/.tox/integration/lib/python3.10/site-packages/_pytest/skipping.py\", line 257, in pytest_runtest_call\n    return (yield)\n  File \"/home/runner/work/postgresql-k8s-operator/postgresql-k8s-operator/.tox/integration/lib/python3.10/site-packages/pluggy/_callers.py\", line 77, in _multicall\n    res = hook_impl.function(*args)\n  File \"/home/runner/work/postgresql-k8s-operator/postgresql-k8s-operator/.tox/integration/lib/python3.10/site-packages/_pytest/runner.py\", line 181, in pytest_runtest_call\n    raise e\n  File \"/home/runner/work/postgresql-k8s-operator/postgresql-k8s-operator/.tox/integration/lib/python3.10/site-packages/_pytest/runner.py\", line 173, in pytest_runtest_call\n    item.runtest()\n  File \"/home/runner/work/postgresql-k8s-operator/postgresql-k8s-operator/.tox/integration/lib/python3.10/site-packages/_pytest/python.py\", line 1836, in runtest\n    self.ihook.pytest_pyfunc_call(pyfuncitem=self)\n  File \"/home/runner/work/postgresql-k8s-operator/postgresql-k8s-operator/.tox/integration/lib/python3.10/site-packages/pluggy/_hooks.py\", line 493, in __call__\n    return self._hookexec(self.name, self._hookimpls, kwargs, firstresult)\n  File \"/home/runner/work/postgresql-k8s-operator/postgresql-k8s-operator/.tox/integration/lib/python3.10/site-packages/pluggy/_manager.py\", line 115, in _hookexec\n    return self._inner_hookexec(hook_name, methods, kwargs, firstresult)\n  File \"/home/runner/work/postgresql-k8s-operator/postgresql-k8s-operator/.tox/integration/lib/python3.10/site-packages/pluggy/_callers.py\", line 152, in _multicall\n    return outcome.get_result()\n  File \"/home/runner/work/postgresql-k8s-operator/postgresql-k8s-operator/.tox/integration/lib/python3.10/site-packages/pluggy/_result.py\", line 114, in get_result\n    raise exc.with_traceback(exc.__traceback__)\n  File \"/home/runner/work/postgresql-k8s-operator/postgresql-k8s-operator/.tox/integration/lib/python3.10/site-packages/pluggy/_callers.py\", line 77, in _multicall\n    res = hook_impl.function(*args)\n  File \"/home/runner/work/postgresql-k8s-operator/postgresql-k8s-operator/.tox/integration/lib/python3.10/site-packages/_pytest/python.py\", line 193, in pytest_pyfunc_call\n    result = testfunction(**testargs)\n  File \"/home/runner/work/postgresql-k8s-operator/postgresql-k8s-operator/.tox/integration/lib/python3.10/site-packages/pytest_asyncio/plugin.py\", line 532, in inner\n    _loop.run_until_complete(task)\n  File \"/usr/lib/python3.10/asyncio/base_events.py\", line 649, in run_until_complete\n    return future.result()\n  File \"/home/runner/work/postgresql-k8s-operator/postgresql-k8s-operator/tests/integration/ha_tests/test_self_healing.py\", line 333, in test_forceful_restart_without_data_and_transaction_logs\n    await is_cluster_updated(ops_test, primary_name)\n  File \"/home/runner/work/postgresql-k8s-operator/postgresql-k8s-operator/tests/integration/ha_tests/helpers.py\", line 156, in is_cluster_updated\n    assert await is_secondary_up_to_date(\nAssertionError: secondary not up to date with the cluster after restarting.","flaky":false,"newFailed":false,"newBroken":false,"newPassed":false,"retriesCount":0,"retriesStatusChange":false,"beforeStages":[{"name":"event_loop","time":{"start":1706750973377,"stop":1706750973377,"duration":0},"status":"passed","steps":[],"attachments":[],"parameters":[],"stepsCount":0,"shouldDisplayMessage":false,"attachmentsCount":0,"hasContent":false,"attachmentStep":false},{"name":"tmp_path_factory","time":{"start":1706750973378,"stop":1706750973378,"duration":0},"status":"passed","steps":[],"attachments":[],"parameters":[],"stepsCount":0,"shouldDisplayMessage":false,"attachmentsCount":0,"hasContent":false,"attachmentStep":false},{"name":"ops_test","time":{"start":1706750973378,"stop":1706750973609,"duration":231},"status":"passed","steps":[],"attachments":[],"parameters":[],"stepsCount":0,"shouldDisplayMessage":false,"attachmentsCount":0,"hasContent":false,"attachmentStep":false},{"name":"primary_start_timeout","time":{"start":1706751268795,"stop":1706751271984,"duration":3189},"status":"passed","steps":[],"attachments":[],"parameters":[],"stepsCount":0,"shouldDisplayMessage":false,"attachmentsCount":0,"hasContent":false,"attachmentStep":false},{"name":"abort_on_fail","time":{"start":1706752239629,"stop":1706752239629,"duration":0},"status":"passed","steps":[],"attachments":[],"parameters":[],"stepsCount":0,"shouldDisplayMessage":false,"attachmentsCount":0,"hasContent":false,"attachmentStep":false},{"name":"continuous_writes","time":{"start":1706752239629,"stop":1706752239629,"duration":0},"status":"passed","steps":[],"attachments":[],"parameters":[],"stepsCount":0,"shouldDisplayMessage":false,"attachmentsCount":0,"hasContent":false,"attachmentStep":false},{"name":"wal_settings","time":{"start":1706752239629,"stop":1706752243831,"duration":4202},"status":"passed","steps":[],"attachments":[],"parameters":[],"stepsCount":0,"shouldDisplayMessage":false,"attachmentsCount":0,"hasContent":false,"attachmentStep":false}],"testStage":{"description":"A forceful restart with deleted data and without transaction logs (forced clone).","status":"failed","statusMessage":"AssertionError: secondary not up to date with the cluster after restarting.","statusTrace":"Traceback (most recent call last):\n  File \"/home/runner/work/postgresql-k8s-operator/postgresql-k8s-operator/.tox/integration/lib/python3.10/site-packages/_pytest/runner.py\", line 345, in from_call\n    result: Optional[TResult] = func()\n  File \"/home/runner/work/postgresql-k8s-operator/postgresql-k8s-operator/.tox/integration/lib/python3.10/site-packages/_pytest/runner.py\", line 266, in <lambda>\n    lambda: ihook(item=item, **kwds), when=when, reraise=reraise\n  File \"/home/runner/work/postgresql-k8s-operator/postgresql-k8s-operator/.tox/integration/lib/python3.10/site-packages/pluggy/_hooks.py\", line 493, in __call__\n    return self._hookexec(self.name, self._hookimpls, kwargs, firstresult)\n  File \"/home/runner/work/postgresql-k8s-operator/postgresql-k8s-operator/.tox/integration/lib/python3.10/site-packages/pluggy/_manager.py\", line 115, in _hookexec\n    return self._inner_hookexec(hook_name, methods, kwargs, firstresult)\n  File \"/home/runner/work/postgresql-k8s-operator/postgresql-k8s-operator/.tox/integration/lib/python3.10/site-packages/pluggy/_callers.py\", line 152, in _multicall\n    return outcome.get_result()\n  File \"/home/runner/work/postgresql-k8s-operator/postgresql-k8s-operator/.tox/integration/lib/python3.10/site-packages/pluggy/_result.py\", line 114, in get_result\n    raise exc.with_traceback(exc.__traceback__)\n  File \"/home/runner/work/postgresql-k8s-operator/postgresql-k8s-operator/.tox/integration/lib/python3.10/site-packages/pluggy/_callers.py\", line 137, in _multicall\n    teardown.throw(outcome._exception)\n  File \"/home/runner/work/postgresql-k8s-operator/postgresql-k8s-operator/.tox/integration/lib/python3.10/site-packages/_pytest/threadexception.py\", line 87, in pytest_runtest_call\n    yield from thread_exception_runtest_hook()\n  File \"/home/runner/work/postgresql-k8s-operator/postgresql-k8s-operator/.tox/integration/lib/python3.10/site-packages/_pytest/threadexception.py\", line 63, in thread_exception_runtest_hook\n    yield\n  File \"/home/runner/work/postgresql-k8s-operator/postgresql-k8s-operator/.tox/integration/lib/python3.10/site-packages/pluggy/_callers.py\", line 137, in _multicall\n    teardown.throw(outcome._exception)\n  File \"/home/runner/work/postgresql-k8s-operator/postgresql-k8s-operator/.tox/integration/lib/python3.10/site-packages/_pytest/unraisableexception.py\", line 90, in pytest_runtest_call\n    yield from unraisable_exception_runtest_hook()\n  File \"/home/runner/work/postgresql-k8s-operator/postgresql-k8s-operator/.tox/integration/lib/python3.10/site-packages/_pytest/unraisableexception.py\", line 65, in unraisable_exception_runtest_hook\n    yield\n  File \"/home/runner/work/postgresql-k8s-operator/postgresql-k8s-operator/.tox/integration/lib/python3.10/site-packages/pluggy/_callers.py\", line 137, in _multicall\n    teardown.throw(outcome._exception)\n  File \"/home/runner/work/postgresql-k8s-operator/postgresql-k8s-operator/.tox/integration/lib/python3.10/site-packages/_pytest/logging.py\", line 839, in pytest_runtest_call\n    yield from self._runtest_for(item, \"call\")\n  File \"/home/runner/work/postgresql-k8s-operator/postgresql-k8s-operator/.tox/integration/lib/python3.10/site-packages/_pytest/logging.py\", line 822, in _runtest_for\n    yield\n  File \"/home/runner/work/postgresql-k8s-operator/postgresql-k8s-operator/.tox/integration/lib/python3.10/site-packages/pluggy/_callers.py\", line 137, in _multicall\n    teardown.throw(outcome._exception)\n  File \"/home/runner/work/postgresql-k8s-operator/postgresql-k8s-operator/.tox/integration/lib/python3.10/site-packages/_pytest/capture.py\", line 882, in pytest_runtest_call\n    return (yield)\n  File \"/home/runner/work/postgresql-k8s-operator/postgresql-k8s-operator/.tox/integration/lib/python3.10/site-packages/pluggy/_callers.py\", line 137, in _multicall\n    teardown.throw(outcome._exception)\n  File \"/home/runner/work/postgresql-k8s-operator/postgresql-k8s-operator/.tox/integration/lib/python3.10/site-packages/_pytest/skipping.py\", line 257, in pytest_runtest_call\n    return (yield)\n  File \"/home/runner/work/postgresql-k8s-operator/postgresql-k8s-operator/.tox/integration/lib/python3.10/site-packages/pluggy/_callers.py\", line 77, in _multicall\n    res = hook_impl.function(*args)\n  File \"/home/runner/work/postgresql-k8s-operator/postgresql-k8s-operator/.tox/integration/lib/python3.10/site-packages/_pytest/runner.py\", line 181, in pytest_runtest_call\n    raise e\n  File \"/home/runner/work/postgresql-k8s-operator/postgresql-k8s-operator/.tox/integration/lib/python3.10/site-packages/_pytest/runner.py\", line 173, in pytest_runtest_call\n    item.runtest()\n  File \"/home/runner/work/postgresql-k8s-operator/postgresql-k8s-operator/.tox/integration/lib/python3.10/site-packages/_pytest/python.py\", line 1836, in runtest\n    self.ihook.pytest_pyfunc_call(pyfuncitem=self)\n  File \"/home/runner/work/postgresql-k8s-operator/postgresql-k8s-operator/.tox/integration/lib/python3.10/site-packages/pluggy/_hooks.py\", line 493, in __call__\n    return self._hookexec(self.name, self._hookimpls, kwargs, firstresult)\n  File \"/home/runner/work/postgresql-k8s-operator/postgresql-k8s-operator/.tox/integration/lib/python3.10/site-packages/pluggy/_manager.py\", line 115, in _hookexec\n    return self._inner_hookexec(hook_name, methods, kwargs, firstresult)\n  File \"/home/runner/work/postgresql-k8s-operator/postgresql-k8s-operator/.tox/integration/lib/python3.10/site-packages/pluggy/_callers.py\", line 152, in _multicall\n    return outcome.get_result()\n  File \"/home/runner/work/postgresql-k8s-operator/postgresql-k8s-operator/.tox/integration/lib/python3.10/site-packages/pluggy/_result.py\", line 114, in get_result\n    raise exc.with_traceback(exc.__traceback__)\n  File \"/home/runner/work/postgresql-k8s-operator/postgresql-k8s-operator/.tox/integration/lib/python3.10/site-packages/pluggy/_callers.py\", line 77, in _multicall\n    res = hook_impl.function(*args)\n  File \"/home/runner/work/postgresql-k8s-operator/postgresql-k8s-operator/.tox/integration/lib/python3.10/site-packages/_pytest/python.py\", line 193, in pytest_pyfunc_call\n    result = testfunction(**testargs)\n  File \"/home/runner/work/postgresql-k8s-operator/postgresql-k8s-operator/.tox/integration/lib/python3.10/site-packages/pytest_asyncio/plugin.py\", line 532, in inner\n    _loop.run_until_complete(task)\n  File \"/usr/lib/python3.10/asyncio/base_events.py\", line 649, in run_until_complete\n    return future.result()\n  File \"/home/runner/work/postgresql-k8s-operator/postgresql-k8s-operator/tests/integration/ha_tests/test_self_healing.py\", line 333, in test_forceful_restart_without_data_and_transaction_logs\n    await is_cluster_updated(ops_test, primary_name)\n  File \"/home/runner/work/postgresql-k8s-operator/postgresql-k8s-operator/tests/integration/ha_tests/helpers.py\", line 156, in is_cluster_updated\n    assert await is_secondary_up_to_date(\nAssertionError: secondary not up to date with the cluster after restarting.","steps":[],"attachments":[{"uid":"3f6aaa93361ba491","name":"log","source":"3f6aaa93361ba491.txt","type":"text/plain","size":3214}],"parameters":[],"stepsCount":0,"shouldDisplayMessage":true,"attachmentsCount":1,"hasContent":true,"attachmentStep":false},"afterStages":[{"name":"wal_settings::finalizer","time":{"start":1706752361126,"stop":1706752361305,"duration":179},"status":"passed","steps":[],"attachments":[],"parameters":[],"stepsCount":0,"shouldDisplayMessage":false,"attachmentsCount":0,"hasContent":false,"attachmentStep":false},{"name":"continuous_writes::finalizer","time":{"start":1706752361306,"stop":1706752362344,"duration":1038},"status":"passed","steps":[],"attachments":[],"parameters":[],"stepsCount":0,"shouldDisplayMessage":false,"attachmentsCount":0,"hasContent":false,"attachmentStep":false},{"name":"abort_on_fail::0","time":{"start":1706752362345,"stop":1706752362345,"duration":0},"status":"passed","steps":[],"attachments":[],"parameters":[],"stepsCount":0,"shouldDisplayMessage":false,"attachmentsCount":0,"hasContent":false,"attachmentStep":false},{"name":"primary_start_timeout::finalizer","time":{"start":1706753837114,"stop":1706753989264,"duration":152150},"status":"broken","statusMessage":"tenacity.RetryError: RetryError[<Future at 0x7ff1898ac460 state=finished raised RetryError>]\n","statusTrace":"  File \"/home/runner/work/postgresql-k8s-operator/postgresql-k8s-operator/.tox/integration/lib/python3.10/site-packages/allure_commons/_allure.py\", line 221, in __call__\n    return self._fixture_function(*args, **kwargs)\n  File \"/home/runner/work/postgresql-k8s-operator/postgresql-k8s-operator/.tox/integration/lib/python3.10/site-packages/pytest_asyncio/plugin.py\", line 302, in finalizer\n    event_loop.run_until_complete(async_finalizer())\n  File \"/usr/lib/python3.10/asyncio/base_events.py\", line 649, in run_until_complete\n    return future.result()\n  File \"/home/runner/work/postgresql-k8s-operator/postgresql-k8s-operator/.tox/integration/lib/python3.10/site-packages/pytest_asyncio/plugin.py\", line 294, in async_finalizer\n    await gen_obj.__anext__()\n  File \"/home/runner/work/postgresql-k8s-operator/postgresql-k8s-operator/tests/integration/ha_tests/conftest.py\", line 68, in primary_start_timeout\n    await change_patroni_setting(ops_test, \"primary_start_timeout\", initial_primary_start_timeout)\n  File \"/home/runner/work/postgresql-k8s-operator/postgresql-k8s-operator/tests/integration/ha_tests/helpers.py\", line 97, in change_patroni_setting\n    for attempt in Retrying(stop=stop_after_delay(30 * 2), wait=wait_fixed(3)):\n  File \"/home/runner/work/postgresql-k8s-operator/postgresql-k8s-operator/.tox/integration/lib/python3.10/site-packages/tenacity/__init__.py\", line 347, in __iter__\n    do = self.iter(retry_state=retry_state)\n  File \"/home/runner/work/postgresql-k8s-operator/postgresql-k8s-operator/.tox/integration/lib/python3.10/site-packages/tenacity/__init__.py\", line 326, in iter\n    raise retry_exc from fut.exception()\n","steps":[],"attachments":[],"parameters":[],"stepsCount":0,"shouldDisplayMessage":true,"attachmentsCount":0,"hasContent":true,"attachmentStep":false},{"name":"ops_test::finalizer","time":{"start":1706753989265,"stop":1706753989615,"duration":350},"status":"passed","steps":[],"attachments":[],"parameters":[],"stepsCount":0,"shouldDisplayMessage":false,"attachmentsCount":0,"hasContent":false,"attachmentStep":false},{"name":"event_loop::2","time":{"start":1706753989616,"stop":1706753989617,"duration":1},"status":"passed","steps":[],"attachments":[],"parameters":[],"stepsCount":0,"shouldDisplayMessage":false,"attachmentsCount":0,"hasContent":false,"attachmentStep":false},{"name":"event_loop::_close_event_loop","time":{"start":1706753989617,"stop":1706753989617,"duration":0},"status":"passed","steps":[],"attachments":[],"parameters":[],"stepsCount":0,"shouldDisplayMessage":false,"attachmentsCount":0,"hasContent":false,"attachmentStep":false},{"name":"event_loop::_provide_clean_event_loop","time":{"start":1706753989617,"stop":1706753989617,"duration":0},"status":"passed","steps":[],"attachments":[],"parameters":[],"stepsCount":0,"shouldDisplayMessage":false,"attachmentsCount":0,"hasContent":false,"attachmentStep":false}],"labels":[{"name":"tag","value":"group(1)"},{"name":"tag","value":"asyncio"},{"name":"parentSuite","value":"tests.integration.ha_tests"},{"name":"suite","value":"test_self_healing"},{"name":"host","value":"fv-az842-902"},{"name":"thread","value":"12336-MainThread"},{"name":"framework","value":"pytest"},{"name":"language","value":"cpython3"},{"name":"package","value":"tests.integration.ha_tests.test_self_healing"},{"name":"resultFormat","value":"allure2"}],"parameters":[],"links":[],"hidden":false,"retry":false,"extra":{"severity":"normal","retries":[],"categories":[{"name":"Product defects","matchedStatuses":[],"flaky":false}],"tags":["asyncio","group(1)"]},"source":"dea77623301df108.json","parameterValues":[]}